Traceback (most recent call last):
  File "/opt/hostedtoolcache/Python/3.10.18/x64/lib/python3.10/site-packages/jupyter_core/utils/__init__.py", line 154, in wrapped
    asyncio.get_running_loop()
RuntimeError: no running event loop

During handling of the above exception, another exception occurred:

Traceback (most recent call last):
  File "/opt/hostedtoolcache/Python/3.10.18/x64/lib/python3.10/site-packages/jupyter_cache/executors/utils.py", line 58, in single_nb_execution
    executenb(
  File "/opt/hostedtoolcache/Python/3.10.18/x64/lib/python3.10/site-packages/nbclient/client.py", line 1319, in execute
    return NotebookClient(nb=nb, resources=resources, km=km, **kwargs).execute()
  File "/opt/hostedtoolcache/Python/3.10.18/x64/lib/python3.10/site-packages/jupyter_core/utils/__init__.py", line 158, in wrapped
    return loop.run_until_complete(inner)
  File "/opt/hostedtoolcache/Python/3.10.18/x64/lib/python3.10/asyncio/base_events.py", line 649, in run_until_complete
    return future.result()
  File "/opt/hostedtoolcache/Python/3.10.18/x64/lib/python3.10/site-packages/nbclient/client.py", line 709, in async_execute
    await self.async_execute_cell(
  File "/opt/hostedtoolcache/Python/3.10.18/x64/lib/python3.10/site-packages/nbclient/client.py", line 1062, in async_execute_cell
    await self._check_raise_for_error(cell, cell_index, exec_reply)
  File "/opt/hostedtoolcache/Python/3.10.18/x64/lib/python3.10/site-packages/nbclient/client.py", line 918, in _check_raise_for_error
    raise CellExecutionError.from_cell_and_msg(cell, exec_reply_content)
nbclient.exceptions.CellExecutionError: An error occurred while executing the following cell:
------------------
results_generator = arxiv.Client(
  page_size=1000,
  delay_seconds=3,
  num_retries=3
).results(arxiv.Search(
  query='"quantum dots"',
  id_list=[],
  sort_by=arxiv.SortCriterion.Relevance,
  sort_order=arxiv.SortOrder.Descending,
))

quantum_dots = []
for paper in results_generator:
  # You could do per-paper analysis here; for now, just collect them in a list.
  quantum_dots.append(paper)
------------------


[0;31m---------------------------------------------------------------------------[0m
[0;31mUnexpectedEmptyPageError[0m                  Traceback (most recent call last)
File [0;32m/opt/hostedtoolcache/Python/3.10.18/x64/lib/python3.10/site-packages/arxiv/__init__.py:648[0m, in [0;36mClient._parse_feed[0;34m(self, url, first_page, _try_index)[0m
[1;32m    647[0m [38;5;28;01mtry[39;00m:
[0;32m--> 648[0m     [38;5;28;01mreturn[39;00m [38;5;28;43mself[39;49m[38;5;241;43m.[39;49m[43m__try_parse_feed[49m[43m([49m[43murl[49m[43m,[49m[43m [49m[43mfirst_page[49m[38;5;241;43m=[39;49m[43mfirst_page[49m[43m,[49m[43m [49m[43mtry_index[49m[38;5;241;43m=[39;49m[43m_try_index[49m[43m)[49m
[1;32m    649[0m [38;5;28;01mexcept[39;00m (
[1;32m    650[0m     HTTPError,
[1;32m    651[0m     UnexpectedEmptyPageError,
[1;32m    652[0m     requests[38;5;241m.[39mexceptions[38;5;241m.[39mConnectionError,
[1;32m    653[0m ) [38;5;28;01mas[39;00m err:

File [0;32m/opt/hostedtoolcache/Python/3.10.18/x64/lib/python3.10/site-packages/arxiv/__init__.py:689[0m, in [0;36mClient.__try_parse_feed[0;34m(self, url, first_page, try_index)[0m
[1;32m    688[0m [38;5;28;01mif[39;00m [38;5;28mlen[39m(feed[38;5;241m.[39mentries) [38;5;241m==[39m [38;5;241m0[39m [38;5;129;01mand[39;00m [38;5;129;01mnot[39;00m first_page:
[0;32m--> 689[0m     [38;5;28;01mraise[39;00m UnexpectedEmptyPageError(url, try_index, feed)
[1;32m    691[0m [38;5;28;01mif[39;00m feed[38;5;241m.[39mbozo:

[0;31mUnexpectedEmptyPageError[0m: Page of results was unexpectedly empty (https://export.arxiv.org/api/query?search_query=%22quantum+dots%22&id_list=&sortBy=relevance&sortOrder=descending&start=1000&max_results=1000)

During handling of the above exception, another exception occurred:

[0;31mUnexpectedEmptyPageError[0m                  Traceback (most recent call last)
File [0;32m/opt/hostedtoolcache/Python/3.10.18/x64/lib/python3.10/site-packages/arxiv/__init__.py:648[0m, in [0;36mClient._parse_feed[0;34m(self, url, first_page, _try_index)[0m
[1;32m    647[0m [38;5;28;01mtry[39;00m:
[0;32m--> 648[0m     [38;5;28;01mreturn[39;00m [38;5;28;43mself[39;49m[38;5;241;43m.[39;49m[43m__try_parse_feed[49m[43m([49m[43murl[49m[43m,[49m[43m [49m[43mfirst_page[49m[38;5;241;43m=[39;49m[43mfirst_page[49m[43m,[49m[43m [49m[43mtry_index[49m[38;5;241;43m=[39;49m[43m_try_index[49m[43m)[49m
[1;32m    649[0m [38;5;28;01mexcept[39;00m (
[1;32m    650[0m     HTTPError,
[1;32m    651[0m     UnexpectedEmptyPageError,
[1;32m    652[0m     requests[38;5;241m.[39mexceptions[38;5;241m.[39mConnectionError,
[1;32m    653[0m ) [38;5;28;01mas[39;00m err:

File [0;32m/opt/hostedtoolcache/Python/3.10.18/x64/lib/python3.10/site-packages/arxiv/__init__.py:689[0m, in [0;36mClient.__try_parse_feed[0;34m(self, url, first_page, try_index)[0m
[1;32m    688[0m [38;5;28;01mif[39;00m [38;5;28mlen[39m(feed[38;5;241m.[39mentries) [38;5;241m==[39m [38;5;241m0[39m [38;5;129;01mand[39;00m [38;5;129;01mnot[39;00m first_page:
[0;32m--> 689[0m     [38;5;28;01mraise[39;00m UnexpectedEmptyPageError(url, try_index, feed)
[1;32m    691[0m [38;5;28;01mif[39;00m feed[38;5;241m.[39mbozo:

[0;31mUnexpectedEmptyPageError[0m: Page of results was unexpectedly empty (https://export.arxiv.org/api/query?search_query=%22quantum+dots%22&id_list=&sortBy=relevance&sortOrder=descending&start=1000&max_results=1000)

During handling of the above exception, another exception occurred:

[0;31mUnexpectedEmptyPageError[0m                  Traceback (most recent call last)
File [0;32m/opt/hostedtoolcache/Python/3.10.18/x64/lib/python3.10/site-packages/arxiv/__init__.py:648[0m, in [0;36mClient._parse_feed[0;34m(self, url, first_page, _try_index)[0m
[1;32m    647[0m [38;5;28;01mtry[39;00m:
[0;32m--> 648[0m     [38;5;28;01mreturn[39;00m [38;5;28;43mself[39;49m[38;5;241;43m.[39;49m[43m__try_parse_feed[49m[43m([49m[43murl[49m[43m,[49m[43m [49m[43mfirst_page[49m[38;5;241;43m=[39;49m[43mfirst_page[49m[43m,[49m[43m [49m[43mtry_index[49m[38;5;241;43m=[39;49m[43m_try_index[49m[43m)[49m
[1;32m    649[0m [38;5;28;01mexcept[39;00m (
[1;32m    650[0m     HTTPError,
[1;32m    651[0m     UnexpectedEmptyPageError,
[1;32m    652[0m     requests[38;5;241m.[39mexceptions[38;5;241m.[39mConnectionError,
[1;32m    653[0m ) [38;5;28;01mas[39;00m err:

File [0;32m/opt/hostedtoolcache/Python/3.10.18/x64/lib/python3.10/site-packages/arxiv/__init__.py:689[0m, in [0;36mClient.__try_parse_feed[0;34m(self, url, first_page, try_index)[0m
[1;32m    688[0m [38;5;28;01mif[39;00m [38;5;28mlen[39m(feed[38;5;241m.[39mentries) [38;5;241m==[39m [38;5;241m0[39m [38;5;129;01mand[39;00m [38;5;129;01mnot[39;00m first_page:
[0;32m--> 689[0m     [38;5;28;01mraise[39;00m UnexpectedEmptyPageError(url, try_index, feed)
[1;32m    691[0m [38;5;28;01mif[39;00m feed[38;5;241m.[39mbozo:

[0;31mUnexpectedEmptyPageError[0m: Page of results was unexpectedly empty (https://export.arxiv.org/api/query?search_query=%22quantum+dots%22&id_list=&sortBy=relevance&sortOrder=descending&start=1000&max_results=1000)

During handling of the above exception, another exception occurred:

[0;31mUnexpectedEmptyPageError[0m                  Traceback (most recent call last)
Cell [0;32mIn[3], line 13[0m
[1;32m      1[0m results_generator [38;5;241m=[39m arxiv[38;5;241m.[39mClient(
[1;32m      2[0m   page_size[38;5;241m=[39m[38;5;241m1000[39m,
[1;32m      3[0m   delay_seconds[38;5;241m=[39m[38;5;241m3[39m,
[0;32m   (...)[0m
[1;32m      9[0m   sort_order[38;5;241m=[39marxiv[38;5;241m.[39mSortOrder[38;5;241m.[39mDescending,
[1;32m     10[0m ))
[1;32m     12[0m quantum_dots [38;5;241m=[39m []
[0;32m---> 13[0m [38;5;28;01mfor[39;00m paper [38;5;129;01min[39;00m results_generator:
[1;32m     14[0m   [38;5;66;03m# You could do per-paper analysis here; for now, just collect them in a list.[39;00m
[1;32m     15[0m   quantum_dots[38;5;241m.[39mappend(paper)

File [0;32m/opt/hostedtoolcache/Python/3.10.18/x64/lib/python3.10/site-packages/arxiv/__init__.py:622[0m, in [0;36mClient._results[0;34m(self, search, offset)[0m
[1;32m    620[0m     [38;5;28;01mbreak[39;00m
[1;32m    621[0m page_url [38;5;241m=[39m [38;5;28mself[39m[38;5;241m.[39m_format_url(search, offset, [38;5;28mself[39m[38;5;241m.[39mpage_size)
[0;32m--> 622[0m feed [38;5;241m=[39m [38;5;28;43mself[39;49m[38;5;241;43m.[39;49m[43m_parse_feed[49m[43m([49m[43mpage_url[49m[43m,[49m[43m [49m[43mfirst_page[49m[38;5;241;43m=[39;49m[38;5;28;43;01mFalse[39;49;00m[43m)[49m

File [0;32m/opt/hostedtoolcache/Python/3.10.18/x64/lib/python3.10/site-packages/arxiv/__init__.py:656[0m, in [0;36mClient._parse_feed[0;34m(self, url, first_page, _try_index)[0m
[1;32m    654[0m [38;5;28;01mif[39;00m _try_index [38;5;241m<[39m [38;5;28mself[39m[38;5;241m.[39mnum_retries:
[1;32m    655[0m     logger[38;5;241m.[39mdebug([38;5;124m"[39m[38;5;124mGot error (try [39m[38;5;132;01m%d[39;00m[38;5;124m): [39m[38;5;132;01m%s[39;00m[38;5;124m"[39m, _try_index, err)
[0;32m--> 656[0m     [38;5;28;01mreturn[39;00m [38;5;28;43mself[39;49m[38;5;241;43m.[39;49m[43m_parse_feed[49m[43m([49m[43murl[49m[43m,[49m[43m [49m[43mfirst_page[49m[38;5;241;43m=[39;49m[43mfirst_page[49m[43m,[49m[43m [49m[43m_try_index[49m[38;5;241;43m=[39;49m[43m_try_index[49m[43m [49m[38;5;241;43m+[39;49m[43m [49m[38;5;241;43m1[39;49m[43m)[49m
[1;32m    657[0m logger[38;5;241m.[39mdebug([38;5;124m"[39m[38;5;124mGiving up (try [39m[38;5;132;01m%d[39;00m[38;5;124m): [39m[38;5;132;01m%s[39;00m[38;5;124m"[39m, _try_index, err)
[1;32m    658[0m [38;5;28;01mraise[39;00m err

File [0;32m/opt/hostedtoolcache/Python/3.10.18/x64/lib/python3.10/site-packages/arxiv/__init__.py:656[0m, in [0;36mClient._parse_feed[0;34m(self, url, first_page, _try_index)[0m
[1;32m    654[0m [38;5;28;01mif[39;00m _try_index [38;5;241m<[39m [38;5;28mself[39m[38;5;241m.[39mnum_retries:
[1;32m    655[0m     logger[38;5;241m.[39mdebug([38;5;124m"[39m[38;5;124mGot error (try [39m[38;5;132;01m%d[39;00m[38;5;124m): [39m[38;5;132;01m%s[39;00m[38;5;124m"[39m, _try_index, err)
[0;32m--> 656[0m     [38;5;28;01mreturn[39;00m [38;5;28;43mself[39;49m[38;5;241;43m.[39;49m[43m_parse_feed[49m[43m([49m[43murl[49m[43m,[49m[43m [49m[43mfirst_page[49m[38;5;241;43m=[39;49m[43mfirst_page[49m[43m,[49m[43m [49m[43m_try_index[49m[38;5;241;43m=[39;49m[43m_try_index[49m[43m [49m[38;5;241;43m+[39;49m[43m [49m[38;5;241;43m1[39;49m[43m)[49m
[1;32m    657[0m logger[38;5;241m.[39mdebug([38;5;124m"[39m[38;5;124mGiving up (try [39m[38;5;132;01m%d[39;00m[38;5;124m): [39m[38;5;132;01m%s[39;00m[38;5;124m"[39m, _try_index, err)
[1;32m    658[0m [38;5;28;01mraise[39;00m err

File [0;32m/opt/hostedtoolcache/Python/3.10.18/x64/lib/python3.10/site-packages/arxiv/__init__.py:656[0m, in [0;36mClient._parse_feed[0;34m(self, url, first_page, _try_index)[0m
[1;32m    654[0m [38;5;28;01mif[39;00m _try_index [38;5;241m<[39m [38;5;28mself[39m[38;5;241m.[39mnum_retries:
[1;32m    655[0m     logger[38;5;241m.[39mdebug([38;5;124m"[39m[38;5;124mGot error (try [39m[38;5;132;01m%d[39;00m[38;5;124m): [39m[38;5;132;01m%s[39;00m[38;5;124m"[39m, _try_index, err)
[0;32m--> 656[0m     [38;5;28;01mreturn[39;00m [38;5;28;43mself[39;49m[38;5;241;43m.[39;49m[43m_parse_feed[49m[43m([49m[43murl[49m[43m,[49m[43m [49m[43mfirst_page[49m[38;5;241;43m=[39;49m[43mfirst_page[49m[43m,[49m[43m [49m[43m_try_index[49m[38;5;241;43m=[39;49m[43m_try_index[49m[43m [49m[38;5;241;43m+[39;49m[43m [49m[38;5;241;43m1[39;49m[43m)[49m
[1;32m    657[0m logger[38;5;241m.[39mdebug([38;5;124m"[39m[38;5;124mGiving up (try [39m[38;5;132;01m%d[39;00m[38;5;124m): [39m[38;5;132;01m%s[39;00m[38;5;124m"[39m, _try_index, err)
[1;32m    658[0m [38;5;28;01mraise[39;00m err

File [0;32m/opt/hostedtoolcache/Python/3.10.18/x64/lib/python3.10/site-packages/arxiv/__init__.py:658[0m, in [0;36mClient._parse_feed[0;34m(self, url, first_page, _try_index)[0m
[1;32m    656[0m     [38;5;28;01mreturn[39;00m [38;5;28mself[39m[38;5;241m.[39m_parse_feed(url, first_page[38;5;241m=[39mfirst_page, _try_index[38;5;241m=[39m_try_index [38;5;241m+[39m [38;5;241m1[39m)
[1;32m    657[0m logger[38;5;241m.[39mdebug([38;5;124m"[39m[38;5;124mGiving up (try [39m[38;5;132;01m%d[39;00m[38;5;124m): [39m[38;5;132;01m%s[39;00m[38;5;124m"[39m, _try_index, err)
[0;32m--> 658[0m [38;5;28;01mraise[39;00m err

File [0;32m/opt/hostedtoolcache/Python/3.10.18/x64/lib/python3.10/site-packages/arxiv/__init__.py:648[0m, in [0;36mClient._parse_feed[0;34m(self, url, first_page, _try_index)[0m
[1;32m    641[0m [38;5;250m[39m[38;5;124;03m"""[39;00m
[1;32m    642[0m [38;5;124;03mFetches the specified URL and parses it with feedparser.[39;00m
[1;32m    643[0m 
[1;32m    644[0m [38;5;124;03mIf a request fails or is unexpectedly empty, retries the request up to[39;00m
[1;32m    645[0m [38;5;124;03m`self.num_retries` times.[39;00m
[1;32m    646[0m [38;5;124;03m"""[39;00m
[1;32m    647[0m [38;5;28;01mtry[39;00m:
[0;32m--> 648[0m     [38;5;28;01mreturn[39;00m [38;5;28;43mself[39;49m[38;5;241;43m.[39;49m[43m__try_parse_feed[49m[43m([49m[43murl[49m[43m,[49m[43m [49m[43mfirst_page[49m[38;5;241;43m=[39;49m[43mfirst_page[49m[43m,[49m[43m [49m[43mtry_index[49m[38;5;241;43m=[39;49m[43m_try_index[49m[43m)[49m
[1;32m    649[0m [38;5;28;01mexcept[39;00m (
[1;32m    650[0m     HTTPError,
[1;32m    651[0m     UnexpectedEmptyPageError,
[1;32m    652[0m     requests[38;5;241m.[39mexceptions[38;5;241m.[39mConnectionError,
[1;32m    653[0m ) [38;5;28;01mas[39;00m err:
[1;32m    654[0m     [38;5;28;01mif[39;00m _try_index [38;5;241m<[39m [38;5;28mself[39m[38;5;241m.[39mnum_retries:

File [0;32m/opt/hostedtoolcache/Python/3.10.18/x64/lib/python3.10/site-packages/arxiv/__init__.py:689[0m, in [0;36mClient.__try_parse_feed[0;34m(self, url, first_page, try_index)[0m
[1;32m    687[0m feed [38;5;241m=[39m feedparser[38;5;241m.[39mparse(resp[38;5;241m.[39mcontent)
[1;32m    688[0m [38;5;28;01mif[39;00m [38;5;28mlen[39m(feed[38;5;241m.[39mentries) [38;5;241m==[39m [38;5;241m0[39m [38;5;129;01mand[39;00m [38;5;129;01mnot[39;00m first_page:
[0;32m--> 689[0m     [38;5;28;01mraise[39;00m UnexpectedEmptyPageError(url, try_index, feed)
[1;32m    691[0m [38;5;28;01mif[39;00m feed[38;5;241m.[39mbozo:
[1;32m    692[0m     logger[38;5;241m.[39mwarning(
[1;32m    693[0m         [38;5;124m"[39m[38;5;124mBozo feed; consider handling: [39m[38;5;132;01m%s[39;00m[38;5;124m"[39m,
[1;32m    694[0m         feed[38;5;241m.[39mbozo_exception [38;5;28;01mif[39;00m [38;5;124m"[39m[38;5;124mbozo_exception[39m[38;5;124m"[39m [38;5;129;01min[39;00m feed [38;5;28;01melse[39;00m [38;5;28;01mNone[39;00m,
[1;32m    695[0m     )

[0;31mUnexpectedEmptyPageError[0m: Page of results was unexpectedly empty (https://export.arxiv.org/api/query?search_query=%22quantum+dots%22&id_list=&sortBy=relevance&sortOrder=descending&start=1000&max_results=1000)

